Workbook

Sheet Total City
A1: city | B1: corrected city
A2: Albany | B2: Albany
A3: Amesbury | B3: Amesbury
A4: Andover | B4: Andover
A5: Arlington | B5: Arlington
A6: Athol | B6: Athol
A7: Attleboro | B7: Attleboro
A8: B0st0n | B8: Boston
A9: B0st0n (MA) | B9: Boston
A10: Barnstable | B10: Barnstable
A11: Berkley | B11: Berkley
A12: Beverly | B12: Beverly
... A124: Yonkers | B124: Yonkers
A127: Albany | C127: {=TRANSPOSE(A127:A236)} -> Albany | D127: Amesbury | E127: Andover | F127: Arlington | G127: Athol | H127: Attleboro | I127: Barnstable | J127: Berkley | K127: Beverly | L127: Billerica | M127: Binghamton | N127: Boston | O127: Bourne | P127: Bridgewater | Q127: Brockton | R127: Brookline | S127: Buffalo | T127: Burlington | U127: Cambridge | V127: Canandaigua | W127: Chatham | X127: City-of-B0st0n | Y127: Clinton Town | Z127: Cooperstown | AA127: Cortland | AB127: Cummington | AC127: Danvers | AD127: Dollard-Des Ormeaux | AE127: Dunstable | AF127: East Buffalo | AG127: East Rochester | AH127: Edgartown | AI127: Elmira | AJ127: Fall River | AK127: Falmouth | AL127: Fitchburg | AM127: Framingham | AN127: Glens Falls | AO127: Great Barrington | AP127: Haverhill | AQ127: Hingham | AR127: Holyoke | AS127: Huntington | AT127: Ithaca | AU127: Jackson | AV127: Lake George | AW127: Lenox | AX127: Leominster | AY127: Levittown | AZ127: Lowell | BA127: Malden | BB127: Mamaroneck | BC127: Manhattan | BD127: Marlborough | BE127: Methuen | BF127: Montauk | BG127: Mount Washington | BH127: Natick | BI127: New Bedford | BJ127: New Paltz | BK127: New Rochelle | BL127: New Rochelle East | BM127: Newark | BN127: Newburgh | BO127: Newburyport | BP127: Niagara Falls | BQ127: Northampton | BR127: Norwood | BS127: Oneonta | BT127: Orange | BU127: Oswego | BV127: Peabody | BW127: Peekskill | BX127: Pembroke | BY127: Pepperell | BZ127: Pittsfield | CA127: Plattsburgh | CB127: Plymouth | CC127: Poughkeepsie | CD127: Princeton | CE127: Queens | CF127: Quincy | CG127: Revere | CH127: Rhinebeck | CI127: Rochester | CJ127: Rosemere | CK127: Saint Laurent | CL127: Saint-Jerome | CM127: Salem | CN127: Scarsdale | CO127: Smithtown | CP127: Somerset | CQ127: Somerville | CR127: Stoughton | CS127: Syracuse | CT127: Taunton | CU127: The Brox | CV127: Utica | CW127: Valley Stream | CX127: Waltham | CY127: Wareham | CZ127: Watertown | DA127: Wellesley | DB127: Westborough | DC127: Weymouth | DD127: Wilmington | DE127: Winchester | DF127: Worcester | DG127: Wrentham | DH127: Yonkers
A128: Amesbury
A129: Andover
A130: Arlington
A131: Athol
A132: Attleboro
A133: Barnstable
A134: Berkley
A135: Beverly
A136: Billerica
A137: Binghamton
A138: Boston
A139: Bourne
... A236: Yonkers

Sheet Popular Category
A3: Sum of stars | B3: Column Labels | O3: Sum of review_count | P3: Column Labels
A4: Row Labels | B4: 1 | C4: 1.5 | D4: 2 | E4: 2.5 | F4: 3 | G4: 3.5 | H4: 4 | I4: 4.5 | J4: 5 | K4: (blank) | L4: Grand Total | O4: Row Labels | P4: 3 | Q4: 4 | R4: 5 | S4: 6 | T4: 7 | U4: 8 | V4: 9 | W4: 10 | X4: 11 | Y4: 12 | Z4: 13 | AA4: 14 | AB4: 15 | AC4: 16 | AD4: 17 | AE4: 18 | AF4: 19 | AG4: 20 | AH4: 21 | AI4: 22 | AJ4: 23 | AK4: 24 | AL4: 25 | AM4: 26 | AN4: 27 | AO4: 28 | AP4: 29 | AQ4: 30 | AR4: 31 | AS4: 32 | AT4: 33 | AU4: 34 | AV4: 35 | AW4: 36 | AX4: 37 | AY4: 38 | AZ4: 39 | BA4: 40 | BB4: 41 | BC4: 42 | BD4: 43 | BE4: 44 | BF4: 45 | BG4: 46 | BH4: 47 | BI4: 48 | BJ4: 49 | BK4: 50 | BL4: 51 | BM4: 52 | BN4: 53 | BO4: 54 | BP4: 55 | BQ4: 56 | BR4: 57 | BS4: 58 | BT4: 59 | BU4: 60 | BV4: 61 | BW4: 62 | BX4: 63 | BY4: 64 | BZ4: 65 | CA4: 66 | CB4: 67 | CC4: 68 | CD4: 69 | CE4: 70 | CF4: 71 | CG4: 72 | CH4: 73 | CI4: 74 | CJ4: 75 | CK4: 76 | CL4: 77 | CM4: 78 | CN4: 79 | CO4: 80 | CP4: 81 | CQ4: 82 | CR4: 83 | CS4: 84 | CT4: 85 | CU4: 86 | CV4: 87 | CW4: 88 | CX4: 89 | CY4: 90 | CZ4: 91 | DA4: 92 | DB4: 93 | DC4: 94 | DD4: 95 | DE4: 96 | DF4: 97 | DG4: 98 | DH4: 99 | DI4: 100 | DJ4: 101 | DK4: 102 | DL4: 103 | DM4: 104 | DN4: 105 | DO4: 106 | DP4: 107 | DQ4: 108 | DR4: 109 | DS4: 110 | DT4: 111 | DU4: 112 | DV4: 113 | DW4: 114 | DX4: 115 | DY4: 116 | DZ4: 117 | EA4: 118 | EB4: 119 | EC4: 120 | ED4: 121 | EE4: 122 | EF4: 123 | EG4: 124 | EH4: 125 | EI4: 126 | EJ4: 127 | EK4: 128 | EL4: 129 | EM4: 130 | EN4: 131 | EO4: 132 | EP4: 133 | EQ4: 134 | ER4: 135 | ES4: 136 | ET4: 137 | EU4: 138 | EV4: 140 | EW4: 141 | EX4: 143 | EY4: 144 | EZ4: 145 | FA4: 146 | FB4: 147 | FC4: 148 | FD4: 149 | FE4: 150 | FF4: 151 | FG4: 153 | FH4: 154 | FI4: 155 | FJ4: 156 | FK4: 157 | FL4: 158 | FM4: 160 | FN4: 162 | FO4: 165 | FP4: 166 | FQ4: 167 | FR4: 168 | FS4: 169 | FT4: 171 | FU4: 172 | FV4: 173 | FW4: 174 | FX4: 175 | FY4: 176 | FZ4: 177 | GA4: 178 | GB4: 179 | GC4: 181 | GD4: 182 | GE4: 183 | GF4: 184 | GG4: 185 | GH4: 188 | GI4: 189 | GJ4: 191 | GK4: 192 | GL4: 193 | GM4: 194 | GN4: 195 | GO4: 198 | GP4: 200 | GQ4: 201 | GR4: 202 | GS4: 203 | GT4: 205 | GU4: 207 | GV4: 208 | GW4: 209 | GX4: 210 | GY4: 213 | GZ4: 216 | HA4: 217 | HB4: 218 | HC4: 221 | HD4: 225 | HE4: 227 | HF4: 228 | HG4: 229 | HH4: 231 | HI4: 232 | HJ4: 233 | HK4: 235 | HL4: 236 | HM4: 239 | HN4: 240 | HO4: 246 | HP4: 247 | HQ4: 254 | HR4: 256 | HS4: 258 | HT4: 259 | HU4: 261 | HV4: 268 | HW4: 270 | HX4: 274 | HY4: 276 | HZ4: 278 | IA4: 279 | IB4: 280 | IC4: 283 | ID4: 291 | IE4: 292 | IF4: 299 | IG4: 309 | IH4: 312 | II4: 316 | IJ4: 318 | IK4: 319 | IL4: 321 | IM4: 324 | IN4: 325 | IO4: 337 | IP4: 338 | IQ4: 342 | IR4: 344 | IS4: 348 | IT4: 351 | IU4: 352 | IV4: 355 | IW4: 359 | IX4: 362 | IY4: 372 | IZ4: 374 | JA4: 377 | JB4: 380 | JC4: 401 | JD4: 428 | JE4: 483 | JF4: 492 | JG4: 511 | JH4: 570 | JI4: 599 | JJ4: 647 | JK4: 678 | JL4: 683 | JM4: 806 | JN4: 982 | JO4: 1087 | JP4: 1241 | JQ4: (blank) | JR4: Grand Total
A5: Restaurants | B5: 8 | C5: 54 | D5: 178 | E5: 395 | F5: 1014 | G5: 1498 | H5: 1604 | I5: 868.5 | J5: 235 | L5: 5854.5 | O5: Restaurants | P5: 660 | Q5: 556 | R5: 480 | S5: 630 | T5: 504 | U5: 544 | V5: 540 | W5: 460 | X5: 572 | Y5: 624 | Z5: 611 | AA5: 434 | AB5: 420 | AC5: 448 | AD5: 510 | AE5: 378 | AF5: 437 | AG5: 380 | AH5: 378 | AI5: 440 | AJ5: 345 | AK5: 288 | AL5: 450 | AM5: 468 | AN5: 540 | AO5: 308 | AP5: 261 | AQ5: 360 | AR5: 496 | AS5: 352 | AT5: 264 | AU5: 408 | AV5: 245 | AW5: 288 | AX5: 444 | AY5: 456 | AZ5: 429 | BA5: 160 | BB5: 533 | BC5: 294 | BD5: 344 | BE5: 132 | BF5: 225 | BG5: 230 | BH5: 235 | BI5: 288 | BJ5: 245 | BK5: 50 | BL5: 357 | BM5: 156 | BN5: 212 | BO5: 648 | BP5: 330 | BQ5: 112 | BR5: 57 | BS5: 174 | BT5: 295 | BU5: 120 | BV5: 244 | BW5: 248 | BX5: 378 | BY5: 320 | BZ5: 585 | CA5: 132 | CB5: 536 | CD5: 414 | CE5: 70 | CF5: 213 | CG5: 288 | CH5: 292 | CI5: 370 | CJ5: 225 | CK5: 152 | CL5: 154 | CM5: 78 | CN5: 316 | CO5: 160 | CP5: 81 | CR5: 332 | CT5: 170 | CU5: 172 | CV5: 174 | CX5: 445 | CY5: 270 | CZ5: 91 | DA5: 184 | DB5: 93 | DC5: 94 | DE5: 192 | DF5: 97 | DG5: 490 | DH5: 297 | DI5: 300 | DJ5: 404 | DK5: 204 | DL5: 103 | DO5: 424 | DP5: 214 | DQ5: 216 | DS5: 110 | DU5: 112 | DX5: 115 | DY5: 232 | DZ5: 351 | EA5: 118 | EE5: 122 | EG5: 372 | EI5: 126 | EJ5: 254 | EL5: 129 | EM5: 130 | EN5: 131 | EO5: 132 | EQ5: 134 | ER5: 270 | ES5: 136 | ET5: 137 | EU5: 414 | EV5: 280 | EX5: 143 | FA5: 146 | FC5: 148 | FE5: 150 | FF5: 151 | FG5: 153 | FL5: 316 | FO5: 165 | FP5: 166 | FR5: 168 | FS5: 169 | FX5: 175 | FZ5: 354 | GD5: 364 | GE5: 183 | GH5: 188 | GI5: 189 | GK5: 192 | GL5: 193 | GM5: 194 | GN5: 390 | GO5: 198 | GP5: 200 | GR5: 202 | GS5: 203 | GT5: 205 | GV5: 208 | GY5: 213 | HA5: 217 | HB5: 218 | HD5: 225 | HJ5: 233 | HK5: 235 | HP5: 247 | HQ5: 254 | IF5: 299 | IM5: 324 | IO5: 337 | IR5: 344 | IS5: 348 | IT5: 351 | JP5: 1241 | JR5: 46231
A6: Food | B6: 2 | C6: 9 | D6: 40 | E6: 110 | F6: 345 | G6: 458.5 | H6: 692 | I6: 463.5 | J6: 150 | L6: 2270 | O6: Food | P6: 270 | Q6: 280 | R6: 280 | S6: 300 | T6: 273 | U6: 248 | V6: 225 | W6: 150 | X6: 176 | Y6: 192 | Z6: 182 | AA6: 224 | AB6: 180 | AC6: 208 | AD6: 153 | AE6: 108 | AF6: 38 | AG6: 120 | AH6: 189 | AI6: 132 | AJ6: 115 | AK6: 120 | AL6: 75 | AM6: 130 | AN6: 54 | AO6: 112 | AP6: 29 | AQ6: 120 | AR6: 124 | AS6: 128 | AT6: 66 | AU6: 136 | AV6: 70 | AW6: 72 | AX6: 37 | AY6: 228 | BA6: 80 | BB6: 41 | BC6: 210 | BE6: 44 | BF6: 45 | BG6: 46 | BH6: 141 | BI6: 48 | BK6: 100 | BL6: 51 | BO6: 162 | BP6: 110 | BQ6: 224 | BR6: 114 | BS6: 58 | BT6: 59 | BW6: 62 | BY6: 64 | BZ6: 65 | CB6: 67 | CD6: 69 | CE6: 140 | CG6: 72 | CH6: 73 | CI6: 74 | CJ6: 75 | CK6: 76 | CL6: 77 | CN6: 79 | CQ6: 164 | CT6: 85 | CX6: 89 | DB6: 93 | DL6: 103 | DP6: 107 | DV6: 113 | DW6: 114 | EA6: 354 | EE6: 122 | EH6: 125 | EO6: 132 | ES6: 136 | FC6: 148 | FE6: 150 | FP6: 166 | FX6: 175 | HF6: 228 | HH6: 231 | HK6: 235 | IB6: 280 | JR6: 11420
A7: Shopping | B7: 6 | C7: 13.5 | D7: 60 | E7: 110 | F7: 147 | G7: 213.5 | H7: 284 | I7: 202.5 | J7: 200 | L7: 1236.5 | O7: Japanese | P7: 24 | Q7: 8 | R7: 30 | S7: 18 | T7: 42 | V7: 36 | W7: 10 | X7: 33 | Y7: 12 | Z7: 26 | AA7: 28 | AB7: 30 | AC7: 64 | AD7: 51 | AE7: 18 | AF7: 38 | AG7: 80 | AH7: 42 | AI7: 88 | AJ7: 23 | AK7: 24 | AL7: 25 | AM7: 26 | AQ7: 30 | AS7: 64 | AT7: 66 | AU7: 102 | AY7: 38 | AZ7: 78 | BA7: 40 | BG7: 46 | BH7: 47 | BL7: 51 | BN7: 53 | BO7: 54 | BP7: 55 | BR7: 57 | BT7: 59 | BW7: 62 | BX7: 126 | CA7: 66 | CH7: 73 | CJ7: 75 | CN7: 79 | CO7: 80 | DA7: 92 | DB7: 93 | DD7: 95 | DM7: 104 | DP7: 107 | DW7: 114 | DY7: 116 | EF7: 123 | EH7: 125 | EL7: 129 | EQ7: 134 | GQ7: 201 | GW7: 209 | HS7: 516 | HU7: 261 | IG7: 309 | JJ7: 647 | JR7: 5552
A8: Beauty & Spas | B8: 6 | C8: 6 | D8: 38 | E8: 67.5 | F8: 111 | G8: 164.5 | H8: 208 | I8: 202.5 | J8: 195 | L8: 998.5 | O8: Nightlife | P8: 60 | Q8: 56 | R8: 65 | S8: 36 | T8: 77 | U8: 56 | V8: 63 | W8: 60 | X8: 44 | Y8: 48 | Z8: 13 | AA8: 28 | AB8: 45 | AC8: 32 | AD8: 68 | AE8: 18 | AF8: 95 | AG8: 80 | AH8: 63 | AI8: 22 | AJ8: 92 | AK8: 24 | AM8: 130 | AN8: 108 | AO8: 56 | AP8: 87 | AR8: 31 | AS8: 64 | AT8: 66 | AV8: 105 | AX8: 148 | AY8: 38 | BA8: 40 | BB8: 82 | BC8: 42 | BF8: 45 | BG8: 46 | BH8: 47 | BN8: 106 | BR8: 57 | BS8: 58 | BT8: 59 | BW8: 62 | CC8: 68 | CH8: 219 | CN8: 79 | CQ8: 82 | CT8: 85 | CV8: 87 | CY8: 90 | CZ8: 91 | DE8: 96 | DF8: 97 | DM8: 104 | DW8: 114 | FS8: 169 | FT8: 171 | FY8: 176 | GA8: 178 | HV8: 268 | IS8: 348 | JR8: 5144
A9: Coffee & Tea | B9: 1 | C9: 6 | D9: 28 | E9: 52.5 | F9: 87 | G9: 192.5 | H9: 208 | I9: 139.5 | J9: 20 | L9: 734.5 | O9: Chinese | P9: 60 | Q9: 32 | R9: 40 | S9: 30 | T9: 42 | U9: 72 | V9: 54 | W9: 50 | X9: 55 | Y9: 36 | Z9: 78 | AA9: 28 | AB9: 30 | AC9: 48 | AD9: 34 | AG9: 80 | AH9: 42 | AI9: 44 | AJ9: 69 | AK9: 24 | AL9: 100 | AN9: 108 | AP9: 29 | AQ9: 30 | AS9: 64 | AT9: 66 | AU9: 102 | AW9: 72 | BA9: 40 | BD9: 86 | BE9: 44 | BG9: 46 | BI9: 96 | BO9: 108 | BY9: 128 | BZ9: 65 | CB9: 67 | CD9: 69 | CG9: 72 | CH9: 73 | CI9: 74 | CO9: 80 | CP9: 81 | CU9: 172 | CV9: 87 | CW9: 176 | CX9: 89 | DI9: 100 | DQ9: 216 | DT9: 111 | EA9: 118 | EL9: 129 | FE9: 150 | FP9: 166 | HO9: 246 | JD9: 428 | JR9: 4836
A10: Nightlife | B10: 1 | C10: 3 | D10: 22 | E10: 40 | F10: 126 | G10: 185.5 | H10: 140 | I10: 76.5 | J10: 30 | L10: 624 | O10: Bars | P10: 45 | Q10: 36 | R10: 40 | S10: 24 | T10: 28 | U10: 24 | V10: 72 | W10: 50 | X10: 33 | Y10: 60 | Z10: 26 | AA10: 42 | AB10: 75 | AC10: 64 | AD10: 34 | AE10: 18 | AF10: 19 | AH10: 84 | AJ10: 46 | AK10: 48 | AM10: 26 | AN10: 27 | AO10: 56 | AP10: 29 | AQ10: 60 | AS10: 32 | AT10: 33 | AU10: 34 | AX10: 37 | BB10: 41 | BE10: 132 | BF10: 45 | BH10: 47 | BI10: 48 | BJ10: 98 | BK10: 50 | BP10: 165 | BQ10: 56 | BR10: 57 | BT10: 59 | BU10: 120 | BV10: 61 | BZ10: 65 | CA10: 66 | CB10: 67 | CC10: 68 | CD10: 69 | CE10: 70 | CH10: 73 | DA10: 92 | DE10: 96 | DH10: 99 | DL10: 103 | DR10: 109 | DY10: 116 | EG10: 124 | EH10: 125 | EK10: 128 | EO10: 132 | FB10: 147 | GM10: 194 | IZ10: 374 | JR10: 4498
A11: #N/A | B11: 4 | C11: 13.5 | D11: 20 | E11: 45 | F11: 81 | G11: 126 | H11: 100 | I11: 85.5 | J11: 60 | L11: 535 | O11: Canadian (New) | P11: 24 | Q11: 24 | R11: 40 | S11: 24 | T11: 14 | U11: 32 | V11: 45 | W11: 60 | Y11: 24 | AA11: 14 | AB11: 15 | AC11: 16 | AD11: 51 | AG11: 60 | AH11: 21 | AI11: 22 | AJ11: 69 | AK11: 72 | AL11: 25 | AM11: 26 | AN11: 54 | AR11: 62 | AT11: 33 | AU11: 34 | AW11: 36 | AZ11: 78 | BA11: 40 | BB11: 82 | BF11: 45 | BG11: 46 | BH11: 47 | BN11: 106 | BO11: 54 | BR11: 57 | CA11: 66 | CO11: 80 | CP11: 81 | CZ11: 91 | DD11: 95 | DE11: 96 | DU11: 112 | EV11: 140 | FN11: 162 | HR11: 256 | IF11: 299 | IP11: 338 | IW11: 359 | JK11: 678 | JR11: 4305
A12: Chinese | B12: 1 | C12: 1.5 | D12: 12 | E12: 45 | F12: 132 | G12: 164.5 | H12: 112 | I12: 40.5 | J12: 10 | L12: 518.5 | O12: Breakfast & Brunch | P12: 30 | Q12: 20 | R12: 20 | S12: 72 | T12: 49 | U12: 32 | V12: 36 | W12: 30 | Y12: 48 | Z12: 26 | AB12: 45 | AD12: 85 | AE12: 72 | AF12: 76 | AG12: 20 | AH12: 63 | AI12: 22 | AJ12: 23 | AK12: 48 | AL12: 100 | AM12: 26 | AQ12: 30 | AS12: 32 | AV12: 35 | AX12: 37 | AZ12: 39 | BB12: 82 | BD12: 86 | BF12: 45 | BH12: 47 | BJ12: 49 | BL12: 51 | BM12: 104 | BP12: 55 | BR12: 114 | BT12: 59 | BY12: 64 | CA12: 66 | CG12: 72 | CU12: 86 | DC12: 94 | DG12: 98 | DO12: 106 | EF12: 123 | EY12: 144 | HO12: 246 | HT12: 259 | IH12: 312 | IX12: 362 | JR12: 3840
A13: Pizza | B13: 3 | C13: 7.5 | D13: 20 | E13: 57.5 | F13: 81 | G13: 150.5 | H13: 116 | I13: 63 | J13: 15 | L13: 513.5 | O13: #N/A | P13: 90 | Q13: 52 | R13: 80 | S13: 84 | T13: 84 | U13: 32 | V13: 36 | W13: 40 | X13: 33 | Y13: 36 | Z13: 39 | AA13: 42 | AB13: 30 | AC13: 32 | AF13: 38 | AG13: 40 | AI13: 44 | AJ13: 23 | AL13: 25 | AM13: 78 | AN13: 54 | AO13: 56 | AP13: 29 | AQ13: 30 | AR13: 31 | AT13: 66 | AU13: 34 | AV13: 35 | AW13: 144 | AX13: 37 | AY13: 38 | BB13: 82 | BF13: 45 | BG13: 46 | BJ13: 98 | BL13: 51 | BN13: 53 | BT13: 59 | CC13: 136 | CE13: 70 | DD13: 95 | DH13: 99 | DU13: 112 | EZ13: 145 | GZ13: 216 | HP13: 247 | JL13: 683 | JR13: 3749
A14: Italian | B14: 1 | C14: 4.5 | D14: 8 | E14: 25 | F14: 90 | G14: 168 | H14: 124 | I14: 63 | J14: 10 | L14: 493.5 | O14: Coffee & Tea | P14: 81 | Q14: 100 | R14: 80 | S14: 114 | T14: 98 | U14: 112 | V14: 81 | W14: 110 | X14: 66 | Y14: 96 | Z14: 52 | AA14: 70 | AB14: 75 | AC14: 80 | AE14: 36 | AF14: 57 | AG14: 40 | AH14: 63 | AI14: 22 | AK14: 24 | AL14: 25 | AO14: 56 | AQ14: 30 | AT14: 33 | AU14: 136 | AV14: 35 | AW14: 36 | BC14: 42 | BI14: 48 | BL14: 102 | BM14: 104 | CD14: 207 | CG14: 72 | CP14: 162 | CQ14: 82 | DL14: 103 | EP14: 133 | EU14: 138 | EV14: 140 | EW14: 141 | GG14: 185 | HL14: 236 | JR14: 3703
A15: Grand Total | B15: 33 | C15: 118.5 | D15: 426 | E15: 947.5 | F15: 2214 | G15: 3321.5 | H15: 3588 | I15: 2205 | J15: 925 | L15: 13778.5 | O15: Grand Total | P15: 1344 | Q15: 1164 | R15: 1155 | S15: 1332 | T15: 1211 | U15: 1152 | V15: 1188 | W15: 1020 | X15: 1012 | Y15: 1176 | Z15: 1053 | AA15: 910 | AB15: 945 | AC15: 992 | AD15: 986 | AE15: 648 | AF15: 798 | AG15: 900 | AH15: 945 | AI15: 836 | AJ15: 805 | AK15: 672 | AL15: 825 | AM15: 910 | AN15: 945 | AO15: 644 | AP15: 464 | AQ15: 690 | AR15: 744 | AS15: 736 | AT15: 693 | AU15: 986 | AV15: 525 | AW15: 648 | AX15: 740 | AY15: 798 | AZ15: 624 | BA15: 400 | BB15: 943 | BC15: 588 | BD15: 516 | BE15: 352 | BF15: 495 | BG15: 506 | BH15: 611 | BI15: 528 | BJ15: 490 | BK15: 200 | BL15: 663 | BM15: 364 | BN15: 530 | BO15: 1026 | BP15: 715 | BQ15: 392 | BR15: 513 | BS15: 290 | BT15: 649 | BU15: 240 | BV15: 305 | BW15: 434 | BX15: 504 | BY15: 576 | BZ15: 780 | CA15: 396 | CB15: 737 | CC15: 272 | CD15: 828 | CE15: 350 | CF15: 213 | CG15: 576 | CH15: 803 | CI15: 518 | CJ15: 375 | CK15: 228 | CL15: 231 | CM15: 78 | CN15: 553 | CO15: 400 | CP15: 405 | CQ15: 328 | CR15: 332 | CT15: 340 | CU15: 430 | CV15: 348 | CW15: 176 | CX15: 623 | CY15: 360 | CZ15: 273 | DA15: 368 | DB15: 279 | DC15: 188 | DD15: 285 | DE15: 480 | DF15: 194 | DG15: 588 | DH15: 495 | DI15: 400 | DJ15: 404 | DK15: 204 | DL15: 412 | DM15: 208 | DO15: 530 | DP15: 428 | DQ15: 432 | DR15: 109 | DS15: 110 | DT15: 111 | DU15: 336 | DV15: 113 | DW15: 342 | DX15: 115 | DY15: 464 | DZ15: 351 | EA15: 590 | EE15: 244 | EF15: 246 | EG15: 496 | EH15: 375 | EI15: 126 | EJ15: 254 | EK15: 128 | EL15: 387 | EM15: 130 | EN15: 131 | EO15: 396 | EP15: 133 | EQ15: 268 | ER15: 270 | ES15: 272 | ET15: 137 | EU15: 552 | EV15: 560 | EW15: 141 | EX15: 143 | EY15: 144 | EZ15: 145 | FA15: 146 | FB15: 147 | FC15: 296 | FE15: 450 | FF15: 151 | FG15: 153 | FL15: 316 | FN15: 162 | FO15: 165 | FP15: 498 | FR15: 168 | FS15: 338 | FT15: 171 | FX15: 350 | FY15: 176 | FZ15: 354 | GA15: 178 | GD15: 364 | GE15: 183 | GG15: 185 | GH15: 188 | GI15: 189 | GK15: 192 | GL15: 193 | GM15: 388 | GN15: 390 | GO15: 198 | GP15: 200 | GQ15: 201 | GR15: 202 | GS15: 203 | GT15: 205 | GV15: 208 | GW15: 209 | GY15: 213 | GZ15: 216 | HA15: 217 | HB15: 218 | HD15: 225 | HF15: 228 | HH15: 231 | HJ15: 233 | HK15: 470 | HL15: 236 | HO15: 492 | HP15: 494 | HQ15: 254 | HR15: 256 | HS15: 516 | HT15: 259 | HU15: 261 | HV15: 268 | IB15: 280 | IF15: 598 | IG15: 309 | IH15: 312 | IM15: 324 | IO15: 337 | IP15: 338 | IR15: 344 | IS15: 696 | IT15: 351 | IW15: 359 | IX15: 362 | IZ15: 374 | JD15: 428 | JJ15: 647 | JK15: 678 | JL15: 683 | JP15: 1241 | JR15: 93278
A19: Row Labels | B19: Average of stars | F19: Row Labels | G19: Sum of review_count
A20: Massachusetts | B20: 3.6680498 | F20: Queens | G20: 592
A21: Restaurants | B21: 3.6680498 | F21: Restaurants | G21: 130
A22: New Jersey | B22: 3.4272727 | F22: Bakeries | G22: 45
A23: Restaurants | B23: 3.4272727 | F23: Canadian (New) | G23: 44
A24: New York | B24: 3.3574505 | F24: Food | G24: 37
A25: Restaurants | B25: 3.3574505 | F25: Shopping Centers | G25: 26
A26: Grand Total | B26: 3.4478799 | F26: Bars | G26: 23
F27: Pizza | G27: 22
F28: Cafes | G28: 22
F29: Fast Food | G29: 22
F30: Comfort Food | G30: 19
F31: Active Life | G31: 16
F32: Italian | G32: 15
F33: Sushi Bars | G33: 13
F34: Pubs | G34: 13
F35: Vietnamese | G35: 11
F36: Burgers | G36: 11
F37: #N/A | G37: 10
F38: Local Services | G38: 10
... F60: Grand Total | G60: 592

Sheet Business per state
A3: Row Labels | B3: Count of id | C3: Sum of review_count | D3: Average of stars | E3: StdDev of stars
A4: Massachusetts | B4: 2186 | C4: 39148 | D4: 3.6985361 | E4: 0.80326431
A5: New Jersey | B5: 245 | C5: 4210 | D5: 3.3816327 | E5: 0.93556187
A6: New York | B6: 7569 | C6: 168455 | D6: 3.4536927 | E6: 0.88727938
A7: (blank)
A8: Grand Total | B8: 10000 | C8: 211813 | D8: 3.50545 | E8: 0.87679654

Sheet Prep Course_Lesson 0 - Yelp Dat
A1: id | B1: name | C1: city | D1: Normalized City | E1: state | F1: stars | G1: review_count | H1: category
A2: I9Y-4JhE4thXVfw--3Azhg | B2: Invacare Corp. | C2: Manhattan | D2: =VLOOKUP(C2,'Total City'!A:B,2,0) -> Manhattan | E2: New York | F2: 3.5 | G2: 5 | H2: Medical Supplies
A3: CF-QQvee-Z_OPc_E-nkI8Q | B3: Chuck E. Cheese | C3: Newark | D3: =VLOOKUP(C3,'Total City'!A:B,2,0) -> Newark | E3: New Jersey | F3: 3 | G3: 6 | H3: Food Delivery Services
A4: rie_OxMfIxmfMJD8MFyprg | B4: CafÃ© Perko | C4: B0st0n | D4: =VLOOKUP(C4,'Total City'!A:B,2,0) -> Boston | E4: Massachusetts | F4: 4.5 | G4: 9 | H4: Home Services
A5: YsqezpbZ-cgwf9kvWpBvFw | B5: Fay Wong | C5: B0st0n | D5: =VLOOKUP(C5,'Total City'!A:B,2,0) -> Boston | E5: Massachusetts | F5: 2.5 | G5: 6 | H5: Chinese
A6: JdsD9o8OIcW2JV3NubQ_hA | B6: Public Library | C6: Manhattan | D6: =VLOOKUP(C6,'Total City'!A:B,2,0) -> Manhattan | E6: New York | F6: 4 | G6: 4 | H6: Public Services & Government
A7: 3rHMaoarZ13Qrafr2DeFcA | B7: The Zen | C7: Syracuse | D7: =VLOOKUP(C7,'Total City'!A:B,2,0) -> Syracuse | E7: New York | F7: 3 | G7: 17 | H7: Chinese
A8: Mzc-5qTf_eY5mNR7Zn5S2w | B8: Nail's Attraction | C8: Manhattan | D8: =VLOOKUP(C8,'Total City'!A:B,2,0) -> Manhattan | E8: New York | F8: 2.5 | G8: 23 | H8: Nail Salons
A9: Kn57RIWAdnVfJHI1loLXOQ | B9: Super Hakka Restaurant | C9: Manhattan | D9: =VLOOKUP(C9,'Total City'!A:B,2,0) -> Manhattan | E9: New York | F9: 3.5 | G9: 67 | H9: Chinese
A10: nd8gEcA81CCq-CIigvO5YQ | B10: Hakim Optical Factory Outlet | C10: Manhattan | D10: =VLOOKUP(C10,'Total City'!A:B,2,0) -> Manhattan | E10: New York | F10: 2.5 | G10: 3 | H10: Shopping
A11: 7lvogweL-b7av26TUOCf4w | B11: Hey Noodles | C11: Manhattan | D11: =VLOOKUP(C11,'Total City'!A:B,2,0) -> Manhattan | E11: New York | F11: 4 | G11: 6 | H11: Asian Fusion
A12: a7PQyftj6OURt0f5evJRUg | B12: Junction Eatery | C12: Manhattan | D12: =VLOOKUP(C12,'Total City'!A:B,2,0) -> Manhattan | E12: New York | F12: 4 | G12: 15 | H12: Restaurants
A13: zuTA5DZ3FQL33hstBJktNQ | B13: Ci Gusta! | C13: The Bronx | D13: =VLOOKUP(C13,'Total City'!A:B,2,0) -> The Brox | E13: New York | F13: 4 | G13: 16 | H13: Ice Cream & Frozen Yogurt
... A49: fcwk_5aiACu6y7AxpRhUug | B49: Smart Furniture | C49: Buffalo | D49: =VLOOKUP(C49,'Total City'!A:B,2,0) -> Buffalo | E49: New York | F49: 2.5 | G49: 3 | H49: Shopping
A50: gY1EPTJwTo7PVdH935C16i | B50: 40 Northh | C50: Plymouth | D50: =VLOOKUP(C50,'Total City'!A:B,2,0) -> Plymouth | E50: Massachusetts | F50: 4.5 | G50: 8 | H50: #N/A
A51: lEMIuw9EuGrni4eY4FaRQQ | B51: Ella Minnow Children's Bookstore | C51: Manhattan | D51: =VLOOKUP(C51,'Total City'!A:B,2,0) -> Manhattan | E51: New York | F51: 3.5 | G51: 3 | H51: Books
A52: tMxzAzHSFJWjSu6CEjwtJQ | B52: Posies Flower Studio | C52: Manhattan | D52: =VLOOKUP(C52,'Total City'!A:B,2,0) -> Manhattan | E52: New York | F52: 4.5 | G52: 3 | H52: Shopping
A53: jpIEMrCxZ6EHCwRlkMAokg | B53: The Sound Post | C53: Manhattan | D53: =VLOOKUP(C53,'Total City'!A:B,2,0) -> Manhattan | E53: New York | F53: 4 | G53: 5 | H53: Music & DVDs
A54: WeUIaYtfyeX9eQKw_5xeiQ | B54: Caz's Great Fish | C54: Utica | D54: =VLOOKUP(C54,'Total City'!A:B,2,0) -> Utica | E54: New York | F54: 4.5 | G54: 9 | H54: Fish & Chips
A55: eujvfaVhdWgctXEasaYkzA | B55: Seasons Foodmart | C55: Elmira | D55: =VLOOKUP(C55,'Total City'!A:B,2,0) -> Elmira | E55: New York | F55: 3 | G55: 18 | H55: Imported Food
A56: lqc424ErH0U6Z4eg-k_cQQ | B56: Mandy's | C56: B0st0n | D56: =VLOOKUP(C56,'Total City'!A:B,2,0) -> Boston | E56: Massachusetts | F56: 4.5 | G56: 18 | H56: Restaurants
A57: t8voOVIOx0_Q_VrQbgeuSg | B57: A Mano Italian Eatery | C57: Huntington | D57: =VLOOKUP(C57,'Total City'!A:B,2,0) -> Huntington | E57: New York | F57: 3.5 | G57: 3 | H57: Italian
A58: Y2MhasrSTYFJM8O04IqCgQ | B58: Restaurant des Jardiniers | C58: Quincy | D58: =VLOOKUP(C58,'Total City'!A:B,2,0) -> Quincy | E58: Massachusetts | F58: 5 | G58: 8 | H58: Canadian (New)
A59: XmgbQmB8SiFcWVWE1xU3fw | B59: Taberna | C59: B0st0n | D59: =VLOOKUP(C59,'Total City'!A:B,2,0) -> Boston | E59: Massachusetts | F59: 3.5 | G59: 12 | H59: Portuguese
A60: 9jII6Il9Phzm6cobNexo7g | B60: Sobeys | C60: Utica | D60: =VLOOKUP(C60,'Total City'!A:B,2,0) -> Utica | E60: New York | F60: 2.5 | G60: 3 | H60: Bakeries
A61: 4FIEx4XKsnpb5gKB-AJBpg | B61: Cutdle | C61: Manhattan | D61: =VLOOKUP(C61,'Total City'!A:B,2,0) -> Manhattan | E61: New York | F61: 3.5 | G61: 3 | H61: Hair Salons
A62: UOQwnDVFCPm34gg5MqOa8g | B62: Kangoo Jumps New York | C62: Manhattan | D62: =VLOOKUP(C62,'Total City'!A:B,2,0) -> Manhattan | E62: New York | F62: 4.5 | G62: 3 | H62: Gyms
... A86: 0_Twd4emsDeKa91azXGoug | B86: Starbucks | C86: Manhattan | D86: =VLOOKUP(C86,'Total City'!A:B,2,0) -> Manhattan | E86: New York | F86: 4 | G86: 6 | H86: Coffee & Tea
A87: 8WYIG5N1tWsRtjL6DpZxqQ | B87: Graffitti's | C87: Poughkeepsie | D87: =VLOOKUP(C87,'Total City'!A:B,2,0) -> Poughkeepsie | E87: New York | F87: 2 | G87: 5 | H87: #N/A
A88: F7yUPLSIullj2Du6CvTo-Q | B88: The Bear and Firkin Pub | C88: Lake George | D88: =VLOOKUP(C88,'Total City'!A:B,2,0) -> Lake George | E88: New York | F88: 3 | G88: 10 | H88: Pubs
A89: fCdcxvZJjkwh7PbOOWUmJQ | B89: Colaba Cuisine | C89: Yonkers | D89: =VLOOKUP(C89,'Total City'!A:B,2,0) -> Yonkers | E89: New York | F89: 3.5 | G89: 22 | H89: Indian
A90: nN4L8-Zt0l0-J3KzkLjXAw | B90: Thai Delight Restaurant | C90: Poughkeepsie | D90: =VLOOKUP(C90,'Total City'!A:B,2,0) -> Poughkeepsie | E90: New York | F90: 3.5 | G90: 3 | H90: Restaurants
A91: ijdlKGYIiVxuDGu-hMejHg | B91: Top Saigon Restaurant | C91: Niagara Falls | D91: =VLOOKUP(C91,'Total City'!A:B,2,0) -> Niagara Falls | E91: New York | F91: 2.5 | G91: 12 | H91: Vietnamese
A92: c9o0sBdEvER2nBeZ6HS9pw | B92: Cineplex Odeon First The Bronx Place Cinemas | C92: The Bronx | D92: =VLOOKUP(C92,'Total City'!A:B,2,0) -> The Brox | E92: New York | F92: 2.5 | G92: 7 | H92: Cinema
A93: MKviRVX2QxRgGS6juCEeYg | B93: Fantasy Eatery | C93: Manhattan | D93: =VLOOKUP(C93,'Total City'!A:B,2,0) -> Manhattan | E93: New York | F93: 3.5 | G93: 14 | H93: Chinese
A94: ubW9VGPz6CnpDWjTrfHxgQ | B94: Hair Smart | C94: Niagara Falls | D94: =VLOOKUP(C94,'Total City'!A:B,2,0) -> Niagara Falls | E94: New York | F94: 3 | G94: 3 | H94: Beauty & Spas
A95: CWa4v0nmLoa6rm2DjXrdMg | B95: CafÃ© Au Bout de L'isle | C95: Worcester | D95: =VLOOKUP(C95,'Total City'!A:B,2,0) -> Worcester | E95: Massachusetts | F95: 3.5 | G95: 3 | H95: Restaurants
A96: MoX-OXOMuOrxikH5fwuybQ | B96: Star Scarsdale Viet Thai Cuisine | C96: The Bronx | D96: =VLOOKUP(C96,'Total City'!A:B,2,0) -> The Brox | E96: New York | F96: 2.5 | G96: 18 | H96: Thai
A97: 7HrCELR6uv2HkgL7aT_hcQ | B97: Chiado | C97: Manhattan | D97: =VLOOKUP(C97,'Total City'!A:B,2,0) -> Manhattan | E97: New York | F97: 4 | G97: 88 | H97: Seafood
A98: XlhTovG_AP59XLGBmD7ipA | B98: Bridge and Bardot | C98: Manhattan | D98: =VLOOKUP(C98,'Total City'!A:B,2,0) -> Manhattan | E98: New York | F98: 3.5 | G98: 3 | H98: Used
...
