Workbook

Sheet shopping_behavior_updated
A1: customer_id | B1: customer_age | C1: customer_gender | D1: product_id | E1: product_item | F1: product_category | G1: purchase_id | H1: _purchase_id | I1: purchase_amount | J1: customer_location | K1: product_size | L1: product_colour | M1: product_season | N1: product_rating | O1: customer_subscription | P1: purchase_shipping type | Q1: purchase_discount | R1: purchase_promocode | S1: customer_purchase count | T1: purchase_payment type | U1: customer_purchase frequency | V1: purchase_date | W1: Total_Purchase_Count | X1: Total_Spend | Y1: Subscription_status | Z1: Persona
A2: 1 | B2: 55 | C2: Male | D2: 1 | E2: Blouse | F2: Clothing | G2: 1 | H2: 200 | I2: 53 | J2: Kentucky | K2: L | L2: Gray | M2: Winter | N2: 3.1 | O2: 1 | P2: Express | Q2: Yes | R2: Yes | S2: 14 | T2: Venmo | U2: Fortnightly | V2: 45338 | W2: =Table1[[#This Row],[customer_purchase count]]+1 -> 15 | X2: =Table1[[#This Row],[customer_purchase count]]*Rules!$B$3 -> 836.70103 | Y2: =IF(Table1[[#This Row],[customer_subscription]]=1,"Subscribed","Not Subscribed") -> Subscribed
A3: 2 | B3: 19 | C3: Male | D3: 2 | E3: Sweater | F3: Clothing | G3: 2 | H3: 201 | I3: 64 | J3: Maine | K3: L | L3: Maroon | M3: Winter | N3: 3.1 | O3: 1 | P3: Express | Q3: Yes | R3: Yes | S3: 2 | T3: Cash | U3: Fortnightly | V3: 45333 | W3: =Table1[[#This Row],[customer_purchase count]]+1 -> 3 | X3: =Table1[[#This Row],[customer_purchase count]]*Rules!$B$3 -> 119.52872 | Y3: =IF(Table1[[#This Row],[customer_subscription]]=1,"Subscribed","Not Subscribed") -> Subscribed
A4: 3 | B4: 50 | C4: Male | D4: 3 | E4: Jeans | F4: Clothing | G4: 3 | H4: 202 | I4: 73 | J4: Massachusetts | K4: S | L4: Maroon | M4: Spring | N4: 3.1 | O4: 1 | P4: Free Shipping | Q4: Yes | R4: Yes | S4: 23 | T4: Credit Card | U4: Weekly | V4: 45368 | W4: =Table1[[#This Row],[customer_purchase count]]+1 -> 24 | X4: =Table1[[#This Row],[customer_purchase count]]*Rules!$B$3 -> 1374.5803 | Y4: =IF(Table1[[#This Row],[customer_subscription]]=1,"Subscribed","Not Subscribed") -> Subscribed
A5: 4 | B5: 21 | C5: Male | D5: 4 | E5: Sandals | F5: Footwear | G5: 4 | H5: 203 | I5: 90 | J5: Rhode Island | K5: M | L5: Maroon | M5: Spring | N5: 3.5 | O5: 1 | P5: Next Day Air | Q5: Yes | R5: Yes | S5: 49 | T5: PayPal | U5: Weekly | V5: 45432 | W5: =Table1[[#This Row],[customer_purchase count]]+1 -> 50 | X5: =Table1[[#This Row],[customer_purchase count]]*Rules!$B$3 -> 2928.4536 | Y5: =IF(Table1[[#This Row],[customer_subscription]]=1,"Subscribed","Not Subscribed") -> Subscribed
A6: 5 | B6: 45 | C6: Male | D6: 5 | E6: Blouse | F6: Clothing | G6: 5 | H6: 205 | I6: 49 | J6: Oregon | K6: M | L6: Turquoise | M6: Spring | N6: 2.7 | O6: 1 | P6: Free Shipping | Q6: Yes | R6: Yes | S6: 31 | T6: PayPal | U6: Annually | V6: 45388 | W6: =Table1[[#This Row],[customer_purchase count]]+1 -> 32 | X6: =Table1[[#This Row],[customer_purchase count]]*Rules!$B$3 -> 1852.6951 | Y6: =IF(Table1[[#This Row],[customer_subscription]]=1,"Subscribed","Not Subscribed") -> Subscribed
A7: 6 | B7: 46 | C7: Male | D7: 6 | E7: Sneakers | F7: Footwear | G7: 6 | H7: 206 | I7: 20 | J7: Wyoming | K7: M | L7: White | M7: Summer | N7: 2.9 | O7: 1 | P7: Standard | Q7: Yes | R7: Yes | S7: 14 | T7: Venmo | U7: Weekly | V7: 45459 | W7: =Table1[[#This Row],[customer_purchase count]]+1 -> 15 | X7: =Table1[[#This Row],[customer_purchase count]]*Rules!$B$3 -> 836.70103 | Y7: =IF(Table1[[#This Row],[customer_subscription]]=1,"Subscribed","Not Subscribed") -> Subscribed
A8: 7 | B8: 63 | C8: Male | D8: 7 | E8: Shirt | F8: Clothing | G8: 7 | H8: 207 | I8: 85 | J8: Montana | K8: M | L8: Gray | M8: Fall | N8: 3.2 | O8: 1 | P8: Free Shipping | Q8: Yes | R8: Yes | S8: 49 | T8: Cash | U8: Quarterly | V8: 45591 | W8: =Table1[[#This Row],[customer_purchase count]]+1 -> 50 | X8: =Table1[[#This Row],[customer_purchase count]]*Rules!$B$3 -> 2928.4536 | Y8: =IF(Table1[[#This Row],[customer_subscription]]=1,"Subscribed","Not Subscribed") -> Subscribed
A9: 8 | B9: 27 | C9: Male | D9: 8 | E9: Shorts | F9: Clothing | G9: 8 | H9: 208 | I9: 34 | J9: Louisiana | K9: L | L9: Charcoal | M9: Winter | N9: 3.2 | O9: 1 | P9: Free Shipping | Q9: Yes | R9: Yes | S9: 19 | T9: Credit Card | U9: Weekly | V9: 45339 | W9: =Table1[[#This Row],[customer_purchase count]]+1 -> 20 | X9: =Table1[[#This Row],[customer_purchase count]]*Rules!$B$3 -> 1135.5228 | Y9: =IF(Table1[[#This Row],[customer_subscription]]=1,"Subscribed","Not Subscribed") -> Subscribed
A10: 9 | B10: 26 | C10: Male | D10: 9 | E10: Coat | F10: Outerwear | G10: 9 | H10: 209 | I10: 97 | J10: West Virginia | K10: L | L10: Silver | M10: Summer | N10: 2.6 | O10: 1 | P10: Express | Q10: Yes | R10: Yes | S10: 8 | T10: Venmo | U10: Annually | V10: 45531 | W10: =Table1[[#This Row],[customer_purchase count]]+1 -> 9 | X10: =Table1[[#This Row],[customer_purchase count]]*Rules!$B$3 -> 478.11487 | Y10: =IF(Table1[[#This Row],[customer_subscription]]=1,"Subscribed","Not Subscribed") -> Subscribed
A11: 10 | B11: 57 | C11: Male | D11: 10 | E11: Handbag | F11: Accessories | G11: 10 | H11: 211 | I11: 31 | J11: Missouri | K11: M | L11: Pink | M11: Spring | N11: 4.8 | O11: 1 | P11: 2-Day Shipping | Q11: Yes | R11: Yes | S11: 4 | T11: Cash | U11: Quarterly | V11: 45440 | W11: =Table1[[#This Row],[customer_purchase count]]+1 -> 5 | X11: =Table1[[#This Row],[customer_purchase count]]*Rules!$B$3 -> 239.05744 | Y11: =IF(Table1[[#This Row],[customer_subscription]]=1,"Subscribed","Not Subscribed") -> Subscribed
A12: 11 | B12: 53 | C12: Male | D12: 11 | E12: Shoes | F12: Footwear | G12: 11 | H12: 212 | I12: 34 | J12: Arkansas | K12: L | L12: Purple | M12: Fall | N12: 4.1 | O12: 1 | P12: Store Pickup | Q12: Yes | R12: Yes | S12: 26 | T12: Bank Transfer | U12: Bi-Weekly | V12: 45570 | W12: =Table1[[#This Row],[customer_purchase count]]+1 -> 27 | X12: =Table1[[#This Row],[customer_purchase count]]*Rules!$B$3 -> 1553.8733 | Y12: =IF(Table1[[#This Row],[customer_subscription]]=1,"Subscribed","Not Subscribed") -> Subscribed
A13: 12 | B13: 30 | C13: Male | D13: 12 | E13: Shorts | F13: Clothing | G13: 12 | H13: 213 | I13: 68 | J13: Hawaii | K13: S | L13: Olive | M13: Winter | N13: 4.9 | O13: 1 | P13: Store Pickup | Q13: Yes | R13: Yes | S13: 10 | T13: Bank Transfer | U13: Fortnightly | V13: 45311 | W13: =Table1[[#This Row],[customer_purchase count]]+1 -> 11 | X13: =Table1[[#This Row],[customer_purchase count]]*Rules!$B$3 -> 597.64359 | Y13: =IF(Table1[[#This Row],[customer_subscription]]=1,"Subscribed","Not Subscribed") -> Subscribed
... A18: 17 | B18: 25 | C18: Male | D18: 17 | E18: Sunglasses | F18: Accessories | G18: 17 | H18: 219 | I18: 36 | J18: Alabama | K18: S | L18: Gray | M18: Spring | N18: 4.1 | O18: 1 | P18: Next Day Air | Q18: Yes | R18: Yes | S18: 44 | T18: Debit Card | U18: Bi-Weekly | V18: 45430 | W18: =Table1[[#This Row],[customer_purchase count]]+1 -> 45 | X18: =Table1[[#This Row],[customer_purchase count]]*Rules!$B$3 -> 2629.6318 | Y18: =IF(Table1[[#This Row],[customer_subscription]]=1,"Subscribed","Not Subscribed") -> Subscribed
A19: 18 | B19: 53 | C19: Male | D19: 18 | E19: Dress | F19: Clothing | G19: 18 | H19: 220 | I19: 38 | J19: Mississippi | K19: XL | L19: Lavender | M19: Winter | N19: 4.7 | O19: 1 | P19: 2-Day Shipping | Q19: Yes | R19: Yes | S19: 36 | T19: Venmo | U19: Quarterly | V19: 45346 | W19: =Table1[[#This Row],[customer_purchase count]]+1 -> 37 | X19: =Table1[[#This Row],[customer_purchase count]]*Rules!$B$3 -> 2151.5169 | Y19: =IF(Table1[[#This Row],[customer_subscription]]=1,"Subscribed","Not Subscribed") -> Subscribed | Z19: Loyal High Spenders
A20: 19 | B20: 52 | C20: Male | D20: 19 | E20: Sweater | F20: Clothing | G20: 19 | H20: 221 | I20: 48 | J20: Montana | K20: S | L20: Black | M20: Summer | N20: 4.6 | O20: 1 | P20: Free Shipping | Q20: Yes | R20: Yes | S20: 17 | T20: Cash | U20: Weekly | V20: 45466 | W20: =Table1[[#This Row],[customer_purchase count]]+1 -> 18 | X20: =Table1[[#This Row],[customer_purchase count]]*Rules!$B$3 -> 1015.9941 | Y20: =IF(Table1[[#This Row],[customer_subscription]]=1,"Subscribed","Not Subscribed") -> Subscribed
A21: 20 | B21: 66 | C21: Male | D21: 20 | E21: Pants | F21: Clothing | G21: 20 | H21: 223 | I21: 90 | J21: Rhode Island | K21: M | L21: Green | M21: Summer | N21: 3.3 | O21: 1 | P21: Standard | Q21: Yes | R21: Yes | S21: 46 | T21: Debit Card | U21: Bi-Weekly | V21: 45452 | W21: =Table1[[#This Row],[customer_purchase count]]+1 -> 47 | X21: =Table1[[#This Row],[customer_purchase count]]*Rules!$B$3 -> 2749.1605 | Y21: =IF(Table1[[#This Row],[customer_subscription]]=1,"Subscribed","Not Subscribed") -> Subscribed
A22: 21 | B22: 21 | C22: Male | D22: 21 | E22: Pants | F22: Clothing | G22: 21 | H22: 224 | I22: 51 | J22: Louisiana | K22: M | L22: Black | M22: Winter | N22: 2.8 | O22: 1 | P22: Express | Q22: Yes | R22: Yes | S22: 50 | T22: Cash | U22: Every 3 Months | V22: 45641 | W22: =Table1[[#This Row],[customer_purchase count]]+1 -> 51 | X22: =Table1[[#This Row],[customer_purchase count]]*Rules!$B$3 -> 2988.2179 | Y22: =IF(Table1[[#This Row],[customer_subscription]]=1,"Subscribed","Not Subscribed") -> Subscribed
A23: 22 | B23: 31 | C23: Male | D23: 22 | E23: Pants | F23: Clothing | G23: 22 | H23: 225 | I23: 62 | J23: North Carolina | K23: M | L23: Charcoal | M23: Winter | N23: 4.1 | O23: 1 | P23: Store Pickup | Q23: Yes | R23: Yes | S23: 22 | T23: Debit Card | U23: Quarterly | V23: 45308 | W23: =Table1[[#This Row],[customer_purchase count]]+1 -> 23 | X23: =Table1[[#This Row],[customer_purchase count]]*Rules!$B$3 -> 1314.8159 | Y23: =IF(Table1[[#This Row],[customer_subscription]]=1,"Subscribed","Not Subscribed") -> Subscribed
A24: 23 | B24: 56 | C24: Male | D24: 23 | E24: Pants | F24: Clothing | G24: 23 | H24: 226 | I24: 37 | J24: California | K24: M | L24: Peach | M24: Summer | N24: 3.2 | O24: 1 | P24: Store Pickup | Q24: Yes | R24: Yes | S24: 32 | T24: Debit Card | U24: Annually | V24: 45527 | W24: =Table1[[#This Row],[customer_purchase count]]+1 -> 33 | X24: =Table1[[#This Row],[customer_purchase count]]*Rules!$B$3 -> 1912.4595 | Y24: =IF(Table1[[#This Row],[customer_subscription]]=1,"Subscribed","Not Subscribed") -> Subscribed
A25: 24 | B25: 31 | C25: Male | D25: 24 | E25: Pants | F25: Clothing | G25: 24 | H25: 227 | I25: 88 | J25: Oklahoma | K25: XL | L25: White | M25: Winter | N25: 4.4 | O25: 1 | P25: Express | Q25: Yes | R25: Yes | S25: 40 | T25: Credit Card | U25: Weekly | V25: 45627 | W25: =Table1[[#This Row],[customer_purchase count]]+1 -> 41 | X25: =Table1[[#This Row],[customer_purchase count]]*Rules!$B$3 -> 2390.5744 | Y25: =IF(Table1[[#This Row],[customer_subscription]]=1,"Subscribed","Not Subscribed") -> Subscribed | Z25: Loyal High Spenders
A26: 25 | B26: 18 | C26: Male | D26: 25 | E26: Jacket | F26: Outerwear | G26: 25 | H26: 229 | I26: 22 | J26: Florida | K26: M | L26: Green | M26: Fall | N26: 2.9 | O26: 1 | P26: Store Pickup | Q26: Yes | R26: Yes | S26: 16 | T26: Debit Card | U26: Weekly | V26: 45579 | W26: =Table1[[#This Row],[customer_purchase count]]+1 -> 17 | X26: =Table1[[#This Row],[customer_purchase count]]*Rules!$B$3 -> 956.22974 | Y26: =IF(Table1[[#This Row],[customer_subscription]]=1,"Subscribed","Not Subscribed") -> Subscribed | Z26: Young Budget Shoppers
A27: 26 | B27: 18 | C27: Male | D27: 26 | E27: Hoodie | F27: Clothing | G27: 26 | H27: 230 | I27: 25 | J27: Texas | K27: M | L27: Silver | M27: Summer | N27: 3.6 | O27: 1 | P27: Express | Q27: Yes | R27: Yes | S27: 14 | T27: PayPal | U27: Annually | V27: 45465 | W27: =Table1[[#This Row],[customer_purchase count]]+1 -> 15 | X27: =Table1[[#This Row],[customer_purchase count]]*Rules!$B$3 -> 836.70103 | Y27: =IF(Table1[[#This Row],[customer_subscription]]=1,"Subscribed","Not Subscribed") -> Subscribed | Z27: Young Budget Shoppers
A28: 27 | B28: 38 | C28: Male | D28: 27 | E28: Jewelry | F28: Accessories | G28: 27 | H28: 231 | I28: 20 | J28: Nevada | K28: M | L28: Red | M28: Spring | N28: 3.6 | O28: 1 | P28: Next Day Air | Q28: Yes | R28: Yes | S28: 13 | T28: Credit Card | U28: Annually | V28: 45388 | W28: =Table1[[#This Row],[customer_purchase count]]+1 -> 14 | X28: =Table1[[#This Row],[customer_purchase count]]*Rules!$B$3 -> 776.93667 | Y28: =IF(Table1[[#This Row],[customer_subscription]]=1,"Subscribed","Not Subscribed") -> Subscribed
A29: 28 | B29: 56 | C29: Male | D29: 28 | E29: Shorts | F29: Clothing | G29: 28 | H29: 232 | I29: 56 | J29: Kentucky | K29: L | L29: Cyan | M29: Summer | N29: 5 | O29: 1 | P29: Next Day Air | Q29: Yes | R29: Yes | S29: 7 | T29: Bank Transfer | U29: Every 3 Months | V29: 45521 | W29: =Table1[[#This Row],[customer_purchase count]]+1 -> 8 | X29: =Table1[[#This Row],[customer_purchase count]]*Rules!$B$3 -> 418.35051 | Y29: =IF(Table1[[#This Row],[customer_subscription]]=1,"Subscribed","Not Subscribed") -> Subscribed
A30: 29 | B30: 54 | C30: Male | D30: 29 | E30: Handbag | F30: Accessories | G30: 29 | H30: 233 | I30: 94 | J30: North Carolina | K30: M | L30: Gray | M30: Fall | N30: 4.4 | O30: 1 | P30: Free Shipping | Q30: Yes | R30: Yes | S30: 41 | T30: PayPal | U30: Every 3 Months | V30: 45609 | W30: =Table1[[#This Row],[customer_purchase count]]+1 -> 42 | X30: =Table1[[#This Row],[customer_purchase count]]*Rules!$B$3 -> 2450.3387 | Y30: =IF(Table1[[#This Row],[customer_subscription]]=1,"Subscribed","Not Subscribed") -> Subscribed | Z30: Loyal High Spenders
A31: 30 | B31: 31 | C31: Male | D31: 30 | E31: Dress | F31: Clothing | G31: 30 | H31: 235 | I31: 48 | J31: Wyoming | K31: S | L31: Black | M31: Fall | N31: 4.1 | O31: 1 | P31: Store Pickup | Q31: Yes | R31: Yes | S31: 14 | T31: Credit Card | U31: Weekly | V31: 45544 | W31: =Table1[[#This Row],[customer_purchase count]]+1 -> 15 | X31: =Table1[[#This Row],[customer_purchase count]]*Rules!$B$3 -> 836.70103 | Y31: =IF(Table1[[#This Row],[customer_subscription]]=1,"Subscribed","Not Subscribed") -> Subscribed
A32: 31 | B32: 57 | C32: Male | D32: 31 | E32: Jewelry | F32: Accessories | G32: 31 | H32: 236 | I32: 31 | J32: North Carolina | K32: L | L32: Black | M32: Winter | N32: 4.7 | O32: 1 | P32: Standard | Q32: Yes | R32: Yes | S32: 16 | T32: Credit Card | U32: Monthly | V32: 45299 | W32: =Table1[[#This Row],[customer_purchase count]]+1 -> 17 | X32: =Table1[[#This Row],[customer_purchase count]]*Rules!$B$3 -> 956.22974 | Y32: =IF(Table1[[#This Row],[customer_subscription]]=1,"Subscribed","Not Subscribed") -> Subscribed
A33: 32 | B33: 33 | C33: Male | D33: 32 | E33: Dress | F33: Clothing | G33: 32 | H33: 237 | I33: 79 | J33: West Virginia | K33: L | L33: Brown | M33: Winter | N33: 4.7 | O33: 1 | P33: Store Pickup | Q33: Yes | R33: Yes | S33: 45 | T33: Venmo | U33: Monthly | V33: 45314 | W33: =Table1[[#This Row],[customer_purchase count]]+1 -> 46 | X33: =Table1[[#This Row],[customer_purchase count]]*Rules!$B$3 -> 2689.3962 | Y33: =IF(Table1[[#This Row],[customer_subscription]]=1,"Subscribed","Not Subscribed") -> Subscribed | Z33: Loyal High Spenders
A34: 33 | B34: 36 | C34: Male | D34: 33 | E34: Jacket | F34: Outerwear | G34: 33 | H34: 238 | I34: 67 | J34: Kansas | K34: M | L34: Silver | M34: Summer | N34: 4.9 | O34: 1 | P34: Free Shipping | Q34: Yes | R34: Yes | S34: 37 | T34: Venmo | U34: Annually | V34: 45454 | W34: =Table1[[#This Row],[customer_purchase count]]+1 -> 38 | X34: =Table1[[#This Row],[customer_purchase count]]*Rules!$B$3 -> 2211.2813 | Y34: =IF(Table1[[#This Row],[customer_subscription]]=1,"Subscribed","Not Subscribed") -> Subscribed | Z34: Loyal High Spenders
A35: 34 | B35: 54 | C35: Male | D35: 34 | E35: Pants | F35: Clothing | G35: 34 | H35: 239 | I35: 38 | J35: Colorado | K35: L | L35: Green | M35: Summer | N35: 3.3 | O35: 1 | P35: Store Pickup | Q35: Yes | R35: Yes | S35: 45 | T35: Cash | U35: Quarterly | V35: 45474 | W35: =Table1[[#This Row],[customer_purchase count]]+1 -> 46 | X35: =Table1[[#This Row],[customer_purchase count]]*Rules!$B$3 -> 2689.3962 | Y35: =IF(Table1[[#This Row],[customer_subscription]]=1,"Subscribed","Not Subscribed") -> Subscribed | Z35: Loyal High Spenders
A36: 35 | B36: 36 | C36: Male | D36: 35 | E36: T-shirt | F36: Clothing | G36: 35 | H36: 241 | I36: 91 | J36: North Dakota | K36: L | L36: Violet | M36: Spring | N36: 4.6 | O36: 1 | P36: 2-Day Shipping | Q36: Yes | R36: Yes | S36: 38 | T36: PayPal | U36: Quarterly | V36: 45423 | W36: =Table1[[#This Row],[customer_purchase count]]+1 -> 39 | X36: =Table1[[#This Row],[customer_purchase count]]*Rules!$B$3 -> 2271.0456 | Y36: =IF(Table1[[#This Row],[customer_subscription]]=1,"Subscribed","Not Subscribed") -> Subscribed | Z36: Loyal High Spenders
A37: 36 | B37: 54 | C37: Male | D37: 36 | E37: Blouse | F37: Clothing | G37: 36 | H37: 242 | I37: 33 | J37: Massachusetts | K37: M | L37: Cyan | M37: Summer | N37: 4 | O37: 1 | P37: 2-Day Shipping | Q37: Yes | R37: Yes | S37: 48 | T37: Credit Card | U37: Bi-Weekly | V37: 45463 | W37: =Table1[[#This Row],[customer_purchase count]]+1 -> 49 | X37: =Table1[[#This Row],[customer_purchase count]]*Rules!$B$3 -> 2868.6892 | Y37: =IF(Table1[[#This Row],[customer_subscription]]=1,"Subscribed","Not Subscribed") -> Subscribed | Z37: Loyal High Spenders
A38: 37 | B38: 35 | C38: Male | D38: 37 | E38: T-shirt | F38: Clothing | G38: 37 | H38: 243 | I38: 69 | J38: Illinois | K38: M | L38: Maroon | M38: Winter | N38: 4.6 | O38: 1 | P38: Free Shipping | Q38: Yes | R38: Yes | S38: 44 | T38: PayPal | U38: Fortnightly | V38: 45631 | W38: =Table1[[#This Row],[customer_purchase count]]+1 -> 45 | X38: =Table1[[#This Row],[customer_purchase count]]*Rules!$B$3 -> 2629.6318 | Y38: =IF(Table1[[#This Row],[customer_subscription]]=1,"Subscribed","Not Subscribed") -> Subscribed | Z38: Loyal High Spenders
A39: 38 | B39: 35 | C39: Male | D39: 38 | E39: Jeans | F39: Clothing | G39: 38 | H39: 244 | I39: 45 | J39: Indiana | K39: S | L39: Cyan | M39: Summer | N39: 2.8 | O39: 1 | P39: Store Pickup | Q39: Yes | R39: Yes | S39: 10 | T39: PayPal | U39: Weekly | V39: 45519 | W39: =Table1[[#This Row],[customer_purchase count]]+1 -> 11 | X39: =Table1[[#This Row],[customer_purchase count]]*Rules!$B$3 -> 597.64359 | Y39: =IF(Table1[[#This Row],[customer_subscription]]=1,"Subscribed","Not Subscribed") -> Subscribed
A40: 39 | B40: 29 | C40: Male | D40: 39 | E40: Dress | F40: Clothing | G40: 39 | H40: 245 | I40: 37 | J40: Florida | K40: M | L40: Red | M40: Winter | N40: 3.7 | O40: 1 | P40: 2-Day Shipping | Q40: Yes | R40: Yes | S40: 44 | T40: Venmo | U40: Every 3 Months | V40: 45332 | W40: =Table1[[#This Row],[customer_purchase count]]+1 -> 45 | X40: =Table1[[#This Row],[customer_purchase count]]*Rules!$B$3 -> 2629.6318 | Y40: =IF(Table1[[#This Row],[customer_subscription]]=1,"Subscribed","Not Subscribed") -> Subscribed
A41: 40 | B41: 70 | C41: Male | D41: 40 | E41: Pants | F41: Clothing | G41: 40 | H41: 247 | I41: 60 | J41: Arizona | K41: S | L41: Turquoise | M41: Summer | N41: 4.2 | O41: 1 | P41: Express | Q41: Yes | R41: Yes | S41: 18 | T41: Credit Card | U41: Monthly | V41: 45497 | W41: =Table1[[#This Row],[customer_purchase count]]+1 -> 19 | X41: =Table1[[#This Row],[customer_purchase count]]*Rules!$B$3 -> 1075.7585 | Y41: =IF(Table1[[#This Row],[customer_subscription]]=1,"Subscribed","Not Subscribed") -> Subscribed
A42: 41 | B42: 69 | C42: Male | D42: 41 | E42: Handbag | F42: Accessories | G42: 41 | H42: 248 | I42: 76 | J42: Louisiana | K42: L | L42: Beige | M42: Winter | N42: 4.6 | O42: 1 | P42: Next Day Air | Q42: Yes | R42: Yes | S42: 31 | T42: Debit Card | U42: Quarterly | V42: 45345 | W42: =Table1[[#This Row],[customer_purchase count]]+1 -> 32 | X42: =Table1[[#This Row],[customer_purchase count]]*Rules!$B$3 -> 1852.6951 | Y42: =IF(Table1[[#This Row],[customer_subscription]]=1,"Subscribed","Not Subscribed") -> Subscribed
A43: 42 | B43: 67 | C43: Male | D43: 42 | E43: Scarf | F43: Accessories | G43: 42 | H43: 249 | I43: 39 | J43: Alaska | K43: M | L43: Orange | M43: Spring | N43: 4.5 | O43: 1 | P43: Standard | Q43: Yes | R43: Yes | S43: 40 | T43: Venmo | U43: Annually | V43: 45371 | W43: =Table1[[#This Row],[customer_purchase count]]+1 -> 41 | X43: =Table1[[#This Row],[customer_purchase count]]*Rules!$B$3 -> 2390.5744 | Y43: =IF(Table1[[#This Row],[customer_subscription]]=1,"Subscribed","Not Subscribed") -> Subscribed
A44: 43 | B44: 20 | C44: Male | D44: 43 | E44: Coat | F44: Outerwear | G44: 43 | H44: 250 | I44: 100 | J44: Tennessee | K44: M | L44: Beige | M44: Spring | N44: 4.1 | O44: 1 | P44: Free Shipping | Q44: Yes | R44: Yes | S44: 15 | T44: PayPal | U44: Annually | V44: 45427 | W44: =Table1[[#This Row],[customer_purchase count]]+1 -> 16 | X44: =Table1[[#This Row],[customer_purchase count]]*Rules!$B$3 -> 896.46538 | Y44: =IF(Table1[[#This Row],[customer_subscription]]=1,"Subscribed","Not Subscribed") -> Subscribed | Z44: Young Budget Shoppers
...

Sheet Rules
A1: Column A | B1: Column B | C1: Column C
A2: Metric | B2: Value | C2: column Ref | G2: Personas | H2: Criteria | I2: Note | J2: Count | M2: Personas | N2: Customers | O2: Revenue | P2: ARPU
A3: Average of Purchase amount | B3: =AVERAGE(Table1[purchase_amount]) -> 59.764359 | C3: $B$3 | G3: Young Budget Shoppers | H3: Age < 30, Spend < Low Spend, Purchase Count > High Frequency | I3: total quantity between 10 and 18 | J3: 168 | M3: Young Budget Shoppers | N3: 168 | O3: 128493 | P3: =O3/N3 -> 764.83929
A4: Median Total Spend | B4: =MEDIAN(Table1[Total_Spend]) -> 1494.109 | C4: $B$4 | G4: Loyal High Spenders | H4: Age between 36–60, Spend > High Spend, Subscribed | J4: 158 | M4: Loyal High Spenders | N4: 230 | O4: 569076 | P4: =O4/N4 -> 2474.2435
A5: Stdev Total Spend | B5: =STDEV(Table1[Total_Spend]) -> 863.42317 | C5: $B$5 | G5: Occasional Deal Seekers | H5: Purchase Count < Low Frequency, Spend < Low, Unsubscribed | J5: 858 | M5: Occasional Deal Seekers | N5: 858 | O5: 413151 | P5: =O5/N5 -> 481.52797
A6: Median Total Purchase Count | B6: =MEDIAN(Table1[Total_Purchase_Count]) -> 26 | C6: $B$6
A7: STDEV Total Purchase Count | B7: =STDEV(Table1[Total_Purchase_Count]) -> 14.447125 | C7: $B$7
A9: Low Spend | B9: =B4- 0.5*B5 -> 1062.3974 | C9: $B$9
A10: High Spend | B10: =B4+0.5*B5 -> 1925.8206 | C10: $B$10
A11: Moderate spend | B11: between above two
A12: Low Frequency | B12: =B6-0.5*B7 -> 18.776437 | C12: $B$12
A13: High Frequency | B13: =B6+0.5*B7 -> 33.223563 | C13: $B$13
A15: Low limit | B15: Median - 0.5*STDEV
A16: High Limit | B16: Median + 0.5*STDEV
